Workbook

Sheet campaigns-2025-11-21
A1: Name | B1: Name Fixe | C1: Group | D1: Status | E1: ID | F1: Ad Format | G1: Impressions | H1: Clicks | I1: eCPM | J1: Cost | K1: CTR | L1: eCPC | M1: 8aeba7b41c36e0642d3ca7ba44ca9509 - Cnvs. | N1: 8aeba7b41c36e0642d3ca7ba44ca9509 - eCPA | O1: Bidder | P1: Max Daily Budget
A2: CPA - RT TEST - Gay - Video-IS Xvideos - Mobile - USA | B2: {=INDEX(_xlfn.TEXTSPLIT(A2," - "),2)} -> RT TEST | C2: 1c. Scaling - Gay | D2: Running | E2: 7958994 | F2: Video (Video) | G2: 0 | H2: 51 | I2: 0.89318285 | J2: 5.5020063 | K2: 0.82792208 | L2: 0.10788248 | M2: 0 | N2: - | O2: null | P2: Unlimited
A3: CPA - bdsm - Video-IS Xvideos - Android Generic - Other Countries | B3: {=INDEX(_xlfn.TEXTSPLIT(A3," - "),2)} -> bdsm | C3: a99. Archived | D3: Paused | E3: 7791688 | F3: Video (Video) | G3: 0 | H3: 3564 | I3: 0.51149705 | J3: 320.91785 | K3: 0.56805051 | L3: 0.090044291 | M3: 0 | N3: - | O3: null | P3: Unlimited
A4: CPA - bdsm - Video-IS Xvideos - iOS - US | B4: {=INDEX(_xlfn.TEXTSPLIT(A4," - "),2)} -> bdsm | C4: a99. Archived | D4: Paused | E4: 7791640 | F4: Video (Video) | G4: 0 | H4: 118 | I4: 1 | J4: 61.641 | K4: 0.19143103 | L4: 0.52238136 | M4: 0 | N4: - | O4: null | P4: Unlimited
A5: CPA - Disney - Video-IS Xvideos - Android Other - Other Countries | B5: {=INDEX(_xlfn.TEXTSPLIT(A5," - "),2)} -> Disney | C5: 1d. Oceangate | D5: Running | E5: 7791500 | F5: Video (Video) | G5: 0 | H5: 710 | I5: 0.39931736 | J5: 25.862587 | K5: 1.0962373 | L5: 0.036426179 | M5: 0 | N5: - | O5: null | P5: Unlimited
A6: CPA - Disney - Video-IS Xvideos - Android Generic - CA | B6: {=INDEX(_xlfn.TEXTSPLIT(A6," - "),2)} -> Disney | C6: a99. Archived | D6: Paused | E6: 7791474 | F6: Video (Video) | G6: 0 | H6: 320 | I6: 1 | J6: 73.878 | K6: 0.43314654 | L6: 0.23086875 | M6: 0 | N6: - | O6: null | P6: Unlimited
A7: CPA - Disney - Video-IS Xvideos - iOS - US | B7: {=INDEX(_xlfn.TEXTSPLIT(A7," - "),2)} -> Disney | C7: a99. Archived | D7: Paused | E7: 7791454 | F7: Video (Video) | G7: 0 | H7: 250 | I7: 1 | J7: 109.266 | K7: 0.22879944 | L7: 0.437064 | M7: 0 | N7: - | O7: null | P7: Unlimited
A8: CPA - squirt - Video-IS Xvideos - Android Other - Other Countries | B8: {=INDEX(_xlfn.TEXTSPLIT(A8," - "),2)} -> squirt | C8: a99. Archived | D8: Paused | E8: 7791440 | F8: Video (Video) | G8: 0 | H8: 3303 | I8: 0.49228598 | J8: 144.63608 | K8: 1.124215 | L8: 0.043789307 | M8: 0 | N8: - | O8: null | P8: Unlimited
A9: CPA - squirt - Video-IS Xvideos - iOS - AU | B9: {=INDEX(_xlfn.TEXTSPLIT(A9," - "),2)} -> squirt | C9: 1d. Oceangate | D9: Running | E9: 7791418 | F9: Video (Video) | G9: 0 | H9: 9 | I9: 1 | J9: 2.954 | K9: 0.30467163 | L9: 0.32822222 | M9: 0 | N9: - | O9: null | P9: Unlimited
A10: CPA - hairy - Video-IS Xvideos - Android Generic - Other Countries | B10: {=INDEX(_xlfn.TEXTSPLIT(A10," - "),2)} -> hairy | C10: a99. Archived | D10: Paused | E10: 7791308 | F10: Video (Video) | G10: 0 | H10: 8824 | I10: 0.48581268 | J10: 708.28234 | K10: 0.60524043 | L10: 0.080267717 | M10: 0 | N10: - | O10: null | P10: Unlimited
A11: CPA - hairy - Video-IS Xvideos - Windows 10 - Other Countries | B11: {=INDEX(_xlfn.TEXTSPLIT(A11," - "),2)} -> hairy | C11: a99. Archived | D11: Paused | E11: 7791302 | F11: Video (Video) | G11: 0 | H11: 606 | I11: 0.44137586 | J11: 61.103633 | K11: 0.43773792 | L11: 0.10083108 | M11: 0 | N11: - | O11: null | P11: Unlimited
A12: CPA - hairy - Video-IS Xvideos - iOS - CA | B12: {=INDEX(_xlfn.TEXTSPLIT(A12," - "),2)} -> hairy | C12: 1d. Oceangate | D12: Running | E12: 7791274 | F12: Video (Video) | G12: 0 | H12: 70 | I12: 1 | J12: 31.225 | K12: 0.22417934 | L12: 0.44607143 | M12: 0 | N12: - | O12: null | P12: Unlimited
A13: CPA - Category: Asian - Video-IS Xvideos - Android Other - Other Countries | B13: {=INDEX(_xlfn.TEXTSPLIT(A13," - "),2)} -> Category: Asian | C13: a99. Archived | D13: Paused | E13: 7791246 | F13: Video (Video) | G13: 0 | H13: 3024 | I13: 0.5383728 | J13: 130.92042 | K13: 1.2435335 | L13: 0.04329379 | M13: 0 | N13: - | O13: null | P13: Unlimited
... A104: CPA - Category: Latina - Video-IS Xvideos - MacOS - UK | B104: {=INDEX(_xlfn.TEXTSPLIT(A104," - "),2)} -> Category: Latina | C104: 1d. Oceangate | D104: Running | E104: 7762268 | F104: Video (Video) | G104: 0 | H104: 3 | I104: 1 | J104: 0.976 | K104: 0.30737705 | L104: 0.32533333 | M104: 0 | N104: - | O104: null | P104: Unlimited
A105: CPA - moana - Video-IS Xvideos - iOS - USA | B105: {=INDEX(_xlfn.TEXTSPLIT(A105," - "),2)} -> moana | C105: a99. Archived | D105: Paused | E105: 7745056 | F105: Video (Video) | G105: 0 | H105: 178 | I105: 1.8132093 | J105: 100.00393 | K105: 0.32273856 | L105: 0.56181984 | M105: 0 | N105: - | O105: null | P105: 50
A106: CPA - elsa - Video-IS Xvideos - iOS - USA | B106: {=INDEX(_xlfn.TEXTSPLIT(A106," - "),2)} -> elsa | C106: 1b. Launch | D106: Running | E106: 7745024 | F106: Video (Video) | G106: 0 | H106: 41 | I106: 1.4744382 | J106: 31.858186 | K106: 0.18975332 | L106: 0.77702893 | M106: 0 | N106: - | O106: null | P106: 50
A107: CPA - neko - Video-IS Xvideos - iOS - USA | B107: {=INDEX(_xlfn.TEXTSPLIT(A107," - "),2)} -> neko | C107: 1b. Launch | D107: Running | E107: 7744850 | F107: Video (Video) | G107: 0 | H107: 3 | I107: 1.5670629 | J107: 1.4746062 | K107: 0.31880978 | L107: 0.49153539 | M107: 0 | N107: - | O107: null | P107: 50
A108: CPA - saber - Video-IS Xvideos - iOS - USA | B108: {=INDEX(_xlfn.TEXTSPLIT(A108," - "),2)} -> saber | C108: a99. Archived | D108: Paused | E108: 7744704 | F108: Video (Video) | G108: 0 | H108: 147 | I108: 1.8314447 | J108: 100.00604 | K108: 0.26920612 | L108: 0.68031318 | M108: 0 | N108: - | O108: null | P108: 50
A109: CPA - link - Video-IS Xvideos - iOS - USA | B109: {=INDEX(_xlfn.TEXTSPLIT(A109," - "),2)} -> link | C109: a99. Archived | D109: Paused | E109: 7744634 | F109: Video (Video) | G109: 0 | H109: 227 | I109: 1.7401445 | J109: 100.01654 | K109: 0.39494746 | L109: 0.44060152 | M109: 0 | N109: - | O109: null | P109: 50
A110: CPA - zelda - Video-IS Xvideos - iOS - USA | B110: {=INDEX(_xlfn.TEXTSPLIT(A110," - "),2)} -> zelda | C110: 1b. Launch | D110: Running | E110: 7744624 | F110: Video (Video) | G110: 0 | H110: 5 | I110: 1.6023453 | J110: 0.88769928 | K110: 0.90252708 | L110: 0.17753986 | M110: 0 | N110: - | O110: null | P110: 50
A111: CPA - jinx - Video-IS Xvideos - iOS - USA | B111: {=INDEX(_xlfn.TEXTSPLIT(A111," - "),2)} -> jinx | C111: 1b. Launch | D111: Running | E111: 7744612 | F111: Video (Video) | G111: 0 | H111: 0 | I111: 1.6642984 | J111: 2.236817 | K111: 0 | L111: 0 | M111: 0 | N111: - | O111: null | P111: 50
A112: CPA - overwatch - Video-IS Xvideos - iOS - USA | B112: {=INDEX(_xlfn.TEXTSPLIT(A112," - "),2)} -> overwatch | C112: 1b. Launch | D112: Running | E112: 7744578 | F112: Video (Video) | G112: 0 | H112: 3 | I112: 1.620945 | J112: 0.99363927 | K112: 0.48939641 | L112: 0.33121309 | M112: 0 | N112: - | O112: null | P112: 50
A113: CPA - bleach - Video-IS Xvideos - iOS - USA | B113: {=INDEX(_xlfn.TEXTSPLIT(A113," - "),2)} -> bleach | C113: a99. Archived | D113: Paused | E113: 7744412 | F113: Video (Video) | G113: 0 | H113: 209 | I113: 1.6769681 | J113: 100.01102 | K113: 0.3504477 | L113: 0.47852165 | M113: 0 | N113: - | O113: null | P113: 50
A114: CPA - nami - Video-IS Xvideos - iOS - USA | B114: {=INDEX(_xlfn.TEXTSPLIT(A114," - "),2)} -> nami | C114: a99. Archived | D114: Paused | E114: 7744278 | F114: Video (Video) | G114: 0 | H114: 179 | I114: 1.6946905 | J114: 100.0308 | K114: 0.30325619 | L114: 0.55883131 | M114: 0 | N114: - | O114: null | P114: 50
A115: CPA - mummy - Video-IS Xvideos - iOS - USA | B115: {=INDEX(_xlfn.TEXTSPLIT(A115," - "),2)} -> mummy | C115: 1b. Launch | D115: Running | E115: 7744166 | F115: Video (Video) | G115: 0 | H115: 24 | I115: 1.3947063 | J115: 8.2357408 | K115: 0.40643522 | L115: 0.34315587 | M115: 0 | N115: - | O115: null | P115: 50
A116: CPA - zombie - Video-IS Xvideos - iOS - USA | B116: {=INDEX(_xlfn.TEXTSPLIT(A116," - "),2)} -> zombie | C116: 1b. Launch | D116: Running | E116: 7744156 | F116: Video (Video) | G116: 0 | H116: 3 | I116: 1.5945381 | J116: 1.4398679 | K116: 0.33222591 | L116: 0.47995596 | M116: 0 | N116: - | O116: null | P116: 50
... A218: [BASE] CPA - General - Video-IS Xvideos - [Device] - [Region] | B218: {=INDEX(_xlfn.TEXTSPLIT(A218," - "),2)} -> General | C218: 0. Base Campaigns | D218: Paused | E218: 7716844 | F218: Video (Video) | G218: 0 | H218: 0 | I218: 0 | J218: 0 | K218: 0 | L218: 0 | M218: 0 | N218: n/a | O218: null | P218: 50
A219: CPA - bdsm - Video-IS Xvideos - Android Generic - CA | B219: {=INDEX(_xlfn.TEXTSPLIT(A219," - "),2)} -> bdsm | C219: a99. Archived | D219: Paused | E219: 7791660 | F219: Video (Video) | G219: 0 | H219: 416 | I219: 1 | J219: 126.903 | K219: 0.32780943 | L219: 0.30505529 | M219: 1 | N219: 126.903 | O219: null | P219: Unlimited
A220: CPA - bdsm - Video-IS Xvideos - Android Generic - US | B220: {=INDEX(_xlfn.TEXTSPLIT(A220," - "),2)} -> bdsm | C220: a99. Archived | D220: Paused | E220: 7791648 | F220: Video (Video) | G220: 0 | H220: 514 | I220: 1 | J220: 118.199 | K220: 0.43485985 | L220: 0.22995914 | M220: 1 | N220: 118.199 | O220: null | P220: Unlimited
A221: CPA - Disney - Video-IS Xvideos - Android Generic - Other Countries | B221: {=INDEX(_xlfn.TEXTSPLIT(A221," - "),2)} -> Disney | C221: a99. Archived | D221: Paused | E221: 7791498 | F221: Video (Video) | G221: 0 | H221: 1738 | I221: 0.54093621 | J221: 148.62872 | K221: 0.63254744 | L221: 0.085517098 | M221: 1 | N221: 148.62872 | O221: null | P221: Unlimited
A222: CPA - Disney - Video-IS Xvideos - iOS - Other Countries | B222: {=INDEX(_xlfn.TEXTSPLIT(A222," - "),2)} -> Disney | C222: a99. Archived | D222: Paused | E222: 7791490 | F222: Video (Video) | G222: 0 | H222: 544 | I222: 0.41676202 | J222: 98.431688 | K222: 0.23033085 | L222: 0.1809406 | M222: 1 | N222: 98.431688 | O222: null | P222: Unlimited
A223: CPA - squirt - Video-IS Xvideos - Android Generic - Other Countries | B223: {=INDEX(_xlfn.TEXTSPLIT(A223," - "),2)} -> squirt | C223: a99. Archived | D223: Paused | E223: 7791438 | F223: Video (Video) | G223: 0 | H223: 5781 | I223: 0.78732197 | J223: 680.41073 | K223: 0.66893541 | L223: 0.11769776 | M223: 1 | N223: 680.41073 | O223: null | P223: Unlimited
A224: CPA - squirt - Video-IS Xvideos - iOS - Other Countries | B224: {=INDEX(_xlfn.TEXTSPLIT(A224," - "),2)} -> squirt | C224: a99. Archived | D224: Paused | E224: 7791430 | F224: Video (Video) | G224: 0 | H224: 439 | I224: 0.73534863 | J224: 130.86264 | K224: 0.24668465 | L224: 0.29809258 | M224: 1 | N224: 130.86264 | O224: null | P224: Unlimited
A225: CPA - squirt - Video-IS Xvideos - Android Generic - CA | B225: {=INDEX(_xlfn.TEXTSPLIT(A225," - "),2)} -> squirt | C225: a99. Archived | D225: Paused | E225: 7791412 | F225: Video (Video) | G225: 0 | H225: 603 | I225: 1 | J225: 146.534 | K225: 0.41150859 | L225: 0.24300829 | M225: 1 | N225: 146.534 | O225: null | P225: Unlimited
A226: CPA - hairy - Video-IS Xvideos - Android Other - Other Countries | B226: {=INDEX(_xlfn.TEXTSPLIT(A226," - "),2)} -> hairy | C226: 1d. Oceangate | D226: Running | E226: 7791310 | F226: Video (Video) | G226: 0 | H226: 2500 | I226: 0.47320618 | J226: 93.934266 | K226: 1.2594078 | L226: 0.037573706 | M226: 1 | N226: 93.934266 | O226: null | P226: Unlimited
A227: CPA - hairy - Video-IS Xvideos - iOS - Other Countries | B227: {=INDEX(_xlfn.TEXTSPLIT(A227," - "),2)} -> hairy | C227: a99. Archived | D227: Paused | E227: 7791300 | F227: Video (Video) | G227: 0 | H227: 591 | I227: 0.51657277 | J227: 130.89541 | K227: 0.23323546 | L227: 0.22148123 | M227: 1 | N227: 130.89541 | O227: null | P227: Unlimited
A228: CPA - hairy - Video-IS Xvideos - Android Generic - CA | B228: {=INDEX(_xlfn.TEXTSPLIT(A228," - "),2)} -> hairy | C228: a99. Archived | D228: Paused | E228: 7791282 | F228: Video (Video) | G228: 0 | H228: 567 | I228: 1 | J228: 146.181 | K228: 0.38787531 | L228: 0.25781481 | M228: 1 | N228: 146.181 | O228: null | P228: Unlimited
A229: CPA - hairy - Video-IS Xvideos - Android Generic - US | B229: {=INDEX(_xlfn.TEXTSPLIT(A229," - "),2)} -> hairy | C229: a99. Archived | D229: Paused | E229: 7791270 | F229: Video (Video) | G229: 0 | H229: 2155 | I229: 1 | J229: 442.707 | K229: 0.48677794 | L229: 0.20543248 | M229: 1 | N229: 442.707 | O229: null | P229: Unlimited
A230: CPA - Category: Asian - Video-IS Xvideos - Android Generic - Other Countries | B230: {=INDEX(_xlfn.TEXTSPLIT(A230," - "),2)} -> Category: Asian | C230: a99. Archived | D230: Paused | E230: 7791244 | F230: Video (Video) | G230: 0 | H230: 3024 | I230: 0.62239813 | J230: 311.44927 | K230: 0.60431413 | L230: 0.10299248 | M230: 1 | N230: 311.44927 | O230: null | P230: Unlimited
... A278: CPA - Gay - Video-IS Xvideos - Mobile - NZ | B278: {=INDEX(_xlfn.TEXTSPLIT(A278," - "),2)} -> Gay | C278: a99. Archived | D278: Paused | E278: 7754988 | F278: Video (Video) | G278: 0 | H278: 6472 | I278: 0.62957789 | J278: 172.12911 | K278: 2.3671929 | L278: 0.026595969 | M278: 1 | N278: 172.12911 | O278: null | P278: Unlimited
...

Sheet Sheet2
A3: Row Labels | B3: Sum of Cost | C3: Conv
A4: Gay | B4: 44444.778 | C4: 702 | D4: =B4/C4 -> 63.31165
A5: Category: Cartoons/Hentai | B5: 5015.7957 | C5: 86 | D5: =B5/C5 -> 58.323205
A6: Xvideos Anal | B6: 4936.3376 | C6: 33 | D6: =B6/C6 -> 149.58599
A7: squirt | B7: 4211.8959 | C7: 44 | D7: =B7/C7 -> 95.724907
A8: AI | B8: 3851.1228 | C8: 42 | D8: =B8/C8 -> 91.693401
A9: Xvideos MILF | B9: 3839.9265 | C9: 47 | D9: =B9/C9 -> 81.700564
A10: milf | B10: 3594.0264 | C10: 26 | D10: =B10/C10 -> 138.23178
A11: threesome | B11: 3206.3924 | C11: 39 | D11: =B11/C11 -> 82.215189
A12: creampie | B12: 3110.9768 | C12: 21 | D12: =B12/C12 -> 148.14175
A13: pov | B13: 2919.3637 | C13: 35 | D13: =B13/C13 -> 83.410392
A14: Xvideos Hentai | B14: 2631.2782 | C14: 17 | D14: =B14/C14 -> 154.78107
A15: Category: Latina | B15: 2451.4528 | C15: 18 | D15: =B15/C15 -> 136.19182
... A161: Vtuber | B161: 0.55054668 | C161: 0 | D161: =B161/C161 -> #DIV/0!
A162: (blank) | D162: =B162/C162 -> #DIV/0!
A163: General | B163: 0 | C163: 0 | D163: =B163/C163 -> #DIV/0!
A164: Grand Total | B164: 123211.18 | C164: 1468 | D164: =B164/C164 -> 83.931319

Sheet ExoLaunches
A1: keyword | B1: One Word | C1: Cost | D1: Conv | E1: CPA | F1: Launch
A2: stripper, stripper porn, stripper blowjob, stripper sex, stripper xxx, stripper amateur, hot stripper, busty stripper, stripper videos, teen stripper, stripper dancing, stripper anal | B2: {=INDEX(_xlfn.TEXTSPLIT(A2,","),1)} -> stripper | C2: =IFERROR(_xlfn.XLOOKUP(B2,Sheet2!A:A,Sheet2!B:B,"Missing",0),200) -> 7.382 | D2: =IFERROR(_xlfn.XLOOKUP(B2,Sheet2!A:A,Sheet2!C:C,"Missing",0),200) -> 1 | E2: =IFERROR(_xlfn.XLOOKUP(B2,Sheet2!A:A,Sheet2!D:D,"Missing",0),200) -> 7.382 | F2: All Platform
A3: maid, maid porn, sexy maid, hot maid, french maid porn, maid blowjob, maid xxx, maid anal, maid milf, maid videos, naughty maid, asian maid | B3: {=INDEX(_xlfn.TEXTSPLIT(A3,","),1)} -> maid | C3: =IFERROR(_xlfn.XLOOKUP(B3,Sheet2!A:A,Sheet2!B:B,"Missing",0),200) -> 9.912 | D3: =IFERROR(_xlfn.XLOOKUP(B3,Sheet2!A:A,Sheet2!C:C,"Missing",0),200) -> 1 | E3: =IFERROR(_xlfn.XLOOKUP(B3,Sheet2!A:A,Sheet2!D:D,"Missing",0),200) -> 9.912 | F3: All Platform
A4: femdom, femdom porn, femdom domination, femdom mistress, femdom milf, femdom slave, femdom fetish, femdom ass worship, femdom xxx, femdom pegging, femdom handjob, femdom cum | B4: {=INDEX(_xlfn.TEXTSPLIT(A4,","),1)} -> femdom | C4: =IFERROR(_xlfn.XLOOKUP(B4,Sheet2!A:A,Sheet2!B:B,"Missing",0),200) -> 12.795 | D4: =IFERROR(_xlfn.XLOOKUP(B4,Sheet2!A:A,Sheet2!C:C,"Missing",0),200) -> 1 | E4: =IFERROR(_xlfn.XLOOKUP(B4,Sheet2!A:A,Sheet2!D:D,"Missing",0),200) -> 12.795 | F4: All Platform
A5: ahegao, ahegao porn, ahegao face, hentai ahegao, anime ahegao, cum ahegao, ahegao compilation, ahegao xxx, asian ahegao, ahegao teen, cosplay ahegao, big tits ahegao | B5: {=INDEX(_xlfn.TEXTSPLIT(A5,","),1)} -> ahegao | C5: =IFERROR(_xlfn.XLOOKUP(B5,Sheet2!A:A,Sheet2!B:B,"Missing",0),200) -> 18.62603 | D5: =IFERROR(_xlfn.XLOOKUP(B5,Sheet2!A:A,Sheet2!C:C,"Missing",0),200) -> 1 | E5: =IFERROR(_xlfn.XLOOKUP(B5,Sheet2!A:A,Sheet2!D:D,"Missing",0),200) -> 18.62603 | F5: All Platform
A6: pregnant, pregnant porn, pregnant milf, pregnant teen, pregnant sex, pregnant creampie, pregnant blowjob, pregnant fetish, pregnant xxx, pregnant lesbian, pregnant anal, pregnant compilation | B6: {=INDEX(_xlfn.TEXTSPLIT(A6,","),1)} -> pregnant | C6: =IFERROR(_xlfn.XLOOKUP(B6,Sheet2!A:A,Sheet2!B:B,"Missing",0),200) -> 96.715 | D6: =IFERROR(_xlfn.XLOOKUP(B6,Sheet2!A:A,Sheet2!C:C,"Missing",0),200) -> 3 | E6: =IFERROR(_xlfn.XLOOKUP(B6,Sheet2!A:A,Sheet2!D:D,"Missing",0),200) -> 32.238333 | F6: All Platform
A7: goth, goth porn, goth girl, hot goth, goth blowjob, goth sex, goth amateur, goth anal, goth milf, goth xxx, goth cumshot, emo porn | B7: {=INDEX(_xlfn.TEXTSPLIT(A7,","),1)} -> goth | C7: =IFERROR(_xlfn.XLOOKUP(B7,Sheet2!A:A,Sheet2!B:B,"Missing",0),200) -> 142.211 | D7: =IFERROR(_xlfn.XLOOKUP(B7,Sheet2!A:A,Sheet2!C:C,"Missing",0),200) -> 4 | E7: =IFERROR(_xlfn.XLOOKUP(B7,Sheet2!A:A,Sheet2!D:D,"Missing",0),200) -> 35.55275 | F7: All Platform
A8: latex, latex porn, latex fetish, sexy latex, latex bdsm, latex xxx, latex mistress, latex milf, latex gloves fetish, latex anal, latex blowjob, latex videos | B8: {=INDEX(_xlfn.TEXTSPLIT(A8,","),1)} -> latex | C8: =IFERROR(_xlfn.XLOOKUP(B8,Sheet2!A:A,Sheet2!B:B,"Missing",0),200) -> 35.809649 | D8: =IFERROR(_xlfn.XLOOKUP(B8,Sheet2!A:A,Sheet2!C:C,"Missing",0),200) -> 1 | E8: =IFERROR(_xlfn.XLOOKUP(B8,Sheet2!A:A,Sheet2!D:D,"Missing",0),200) -> 35.809649 | F8: All Platform
A9: feet, foot fetish, feet porn, sexy feet, feet worship, footjob, feet licking, feet xxx, feet cumshot, feet tease, feet milf, feet pics | B9: {=INDEX(_xlfn.TEXTSPLIT(A9,","),1)} -> feet | C9: =IFERROR(_xlfn.XLOOKUP(B9,Sheet2!A:A,Sheet2!B:B,"Missing",0),200) -> 226.337 | D9: =IFERROR(_xlfn.XLOOKUP(B9,Sheet2!A:A,Sheet2!C:C,"Missing",0),200) -> 6 | E9: =IFERROR(_xlfn.XLOOKUP(B9,Sheet2!A:A,Sheet2!D:D,"Missing",0),200) -> 37.722833 | F9: All Platform
A10: public, public porn, public sex, in public, public blowjob, public xxx, public fap, public fetish, public creampie, public amateur, public flashing, outdoor sex | B10: {=INDEX(_xlfn.TEXTSPLIT(A10,","),1)} -> public | C10: =IFERROR(_xlfn.XLOOKUP(B10,Sheet2!A:A,Sheet2!B:B,"Missing",0),200) -> 306.162 | D10: =IFERROR(_xlfn.XLOOKUP(B10,Sheet2!A:A,Sheet2!C:C,"Missing",0),200) -> 6 | E10: =IFERROR(_xlfn.XLOOKUP(B10,Sheet2!A:A,Sheet2!D:D,"Missing",0),200) -> 51.027 | F10: All Platform
A11: orgy, orgy porn, orgy sex, group sex, amateur orgy, teen orgy, milf orgy, interracial orgy, lesbian orgy, orgy xxx, sex party porn, hardcore orgy | B11: {=INDEX(_xlfn.TEXTSPLIT(A11,","),1)} -> orgy | C11: =IFERROR(_xlfn.XLOOKUP(B11,Sheet2!A:A,Sheet2!B:B,"Missing",0),200) -> 359.60758 | D11: =IFERROR(_xlfn.XLOOKUP(B11,Sheet2!A:A,Sheet2!C:C,"Missing",0),200) -> 7 | E11: =IFERROR(_xlfn.XLOOKUP(B11,Sheet2!A:A,Sheet2!D:D,"Missing",0),200) -> 51.372512 | F11: All Platform
A12: straight, straight porn, straight sex, straight couple sex, straight amateur, straight videos, straight blowjob, straight xxx, straight anal, straight creampie, straight fuck, straight teens | B12: {=INDEX(_xlfn.TEXTSPLIT(A12,","),1)} -> straight | C12: =IFERROR(_xlfn.XLOOKUP(B12,Sheet2!A:A,Sheet2!B:B,"Missing",0),200) -> 159.945 | D12: =IFERROR(_xlfn.XLOOKUP(B12,Sheet2!A:A,Sheet2!C:C,"Missing",0),200) -> 3 | E12: =IFERROR(_xlfn.XLOOKUP(B12,Sheet2!A:A,Sheet2!D:D,"Missing",0),200) -> 53.315 | F12: All Platform
A13: fisting, fisting porn, anal fisting, double fisting, fist fuck, hardcore fisting, lesbian fisting, milf fisting, fisting xxx, fisting compilation, extreme fisting, teen fisting | B13: {=INDEX(_xlfn.TEXTSPLIT(A13,","),1)} -> fisting | C13: =IFERROR(_xlfn.XLOOKUP(B13,Sheet2!A:A,Sheet2!B:B,"Missing",0),200) -> 109.379 | D13: =IFERROR(_xlfn.XLOOKUP(B13,Sheet2!A:A,Sheet2!C:C,"Missing",0),200) -> 2 | E13: =IFERROR(_xlfn.XLOOKUP(B13,Sheet2!A:A,Sheet2!D:D,"Missing",0),200) -> 54.6895 | F13: All Platform
... A32: bdsm, bdsm porn, bdsm sex, bdsm xxx, bdsm girl, bdsm slave, bdsm blowjob, bdsm anal, bdsm mistress, bdsm milf, bdsm fetish, hardcore bdsm, bdsm video | B32: {=INDEX(_xlfn.TEXTSPLIT(A32,","),1)} -> bdsm | C32: =IFERROR(_xlfn.XLOOKUP(B32,Sheet2!A:A,Sheet2!B:B,"Missing",0),200) -> 1065.3882 | D32: =IFERROR(_xlfn.XLOOKUP(B32,Sheet2!A:A,Sheet2!C:C,"Missing",0),200) -> 11 | E32: =IFERROR(_xlfn.XLOOKUP(B32,Sheet2!A:A,Sheet2!D:D,"Missing",0),200) -> 96.853475 | F32: Split Platform
A33: mature, mature porn, mature milf, mature woman, sexy mature, mature anal, mature creampie, mature big tits, mature xxx, mature blowjob, mature threesome, mature amateur | B33: {=INDEX(_xlfn.TEXTSPLIT(A33,","),1)} -> mature | C33: =IFERROR(_xlfn.XLOOKUP(B33,Sheet2!A:A,Sheet2!B:B,"Missing",0),200) -> 100.004 | D33: =IFERROR(_xlfn.XLOOKUP(B33,Sheet2!A:A,Sheet2!C:C,"Missing",0),200) -> 1 | E33: =IFERROR(_xlfn.XLOOKUP(B33,Sheet2!A:A,Sheet2!D:D,"Missing",0),200) -> 100.004 | F33: =IFERROR(_xlfn.XLOOKUP(C33,Sheet2!B:B,Sheet2!E:E,"Missing",0),200) -> 0
A34: clown, clown porn, clown sex, clown xxx, clown blowjob, clown milf, clown fetish, clown roleplay, clown compilation, clown anal, clown lingerie porn, clown gangbang | B34: {=INDEX(_xlfn.TEXTSPLIT(A34,","),1)} -> clown | C34: =IFERROR(_xlfn.XLOOKUP(B34,Sheet2!A:A,Sheet2!B:B,"Missing",0),200) -> 100.02004 | D34: =IFERROR(_xlfn.XLOOKUP(B34,Sheet2!A:A,Sheet2!C:C,"Missing",0),200) -> 1 | E34: =IFERROR(_xlfn.XLOOKUP(B34,Sheet2!A:A,Sheet2!D:D,"Missing",0),200) -> 100.02004 | F34: All Platform
A35: stepmom, stepmom porn, hot stepmom, stepmom sex, mature stepmom, big tits stepmom, naughty stepmom, sexy stepmom, stepmom blowjob, stepmom videos, milf stepmom, stepmom anal | B35: {=INDEX(_xlfn.TEXTSPLIT(A35,","),1)} -> stepmom | C35: =IFERROR(_xlfn.XLOOKUP(B35,Sheet2!A:A,Sheet2!B:B,"Missing",0),200) -> 100.021 | D35: =IFERROR(_xlfn.XLOOKUP(B35,Sheet2!A:A,Sheet2!C:C,"Missing",0),200) -> 1 | E35: =IFERROR(_xlfn.XLOOKUP(B35,Sheet2!A:A,Sheet2!D:D,"Missing",0),200) -> 100.021 | F35: =IFERROR(_xlfn.XLOOKUP(C35,Sheet2!B:B,Sheet2!E:E,"Missing",0),200) -> 0
A36: club, club porn, sex club, swinger club, club sex video, club gangbang, night club porn, club orgy, club xxx, club fuck, club amateur, club teens | B36: {=INDEX(_xlfn.TEXTSPLIT(A36,","),1)} -> club | C36: =IFERROR(_xlfn.XLOOKUP(B36,Sheet2!A:A,Sheet2!B:B,"Missing",0),200) -> 100.031 | D36: =IFERROR(_xlfn.XLOOKUP(B36,Sheet2!A:A,Sheet2!C:C,"Missing",0),200) -> 1 | E36: =IFERROR(_xlfn.XLOOKUP(B36,Sheet2!A:A,Sheet2!D:D,"Missing",0),200) -> 100.031 | F36: =IFERROR(_xlfn.XLOOKUP(C36,Sheet2!B:B,Sheet2!E:E,"Missing",0),200) -> 0
A37: witch, witch porn, witch milf, witch sex, witch xxx, sexy witch, hentai witch, witch fetish, witch blowjob, witch strip, halloween witch porn, demon witch sex | B37: {=INDEX(_xlfn.TEXTSPLIT(A37,","),1)} -> witch | C37: =IFERROR(_xlfn.XLOOKUP(B37,Sheet2!A:A,Sheet2!B:B,"Missing",0),200) -> 100.04883 | D37: =IFERROR(_xlfn.XLOOKUP(B37,Sheet2!A:A,Sheet2!C:C,"Missing",0),200) -> 1 | E37: =IFERROR(_xlfn.XLOOKUP(B37,Sheet2!A:A,Sheet2!D:D,"Missing",0),200) -> 100.04883 | F37: =IFERROR(_xlfn.XLOOKUP(C37,Sheet2!B:B,Sheet2!E:E,"Missing",0),200) -> 0
A38: spanish, spanish porn, spanish sex, spanish milf, spanish teen, spanish anal, spanish blowjob, spanish videos, hot spanish girl, spanish xxx, spanish amateur, spanish creampie | B38: {=INDEX(_xlfn.TEXTSPLIT(A38,","),1)} -> spanish | C38: =IFERROR(_xlfn.XLOOKUP(B38,Sheet2!A:A,Sheet2!B:B,"Missing",0),200) -> 100.054 | D38: =IFERROR(_xlfn.XLOOKUP(B38,Sheet2!A:A,Sheet2!C:C,"Missing",0),200) -> 1 | E38: =IFERROR(_xlfn.XLOOKUP(B38,Sheet2!A:A,Sheet2!D:D,"Missing",0),200) -> 100.054 | F38: =IFERROR(_xlfn.XLOOKUP(C38,Sheet2!B:B,Sheet2!E:E,"Missing",0),200) -> 0
A39: triple, triple penetration porn, triple xxx, triple sex, triple milf, triple fetish, triple anal, double anal triple, triple creampie, triple blowjob, hardcore triple, triple gangbang | B39: {=INDEX(_xlfn.TEXTSPLIT(A39,","),1)} -> triple | C39: =IFERROR(_xlfn.XLOOKUP(B39,Sheet2!A:A,Sheet2!B:B,"Missing",0),200) -> 100.06015 | D39: =IFERROR(_xlfn.XLOOKUP(B39,Sheet2!A:A,Sheet2!C:C,"Missing",0),200) -> 1 | E39: =IFERROR(_xlfn.XLOOKUP(B39,Sheet2!A:A,Sheet2!D:D,"Missing",0),200) -> 100.06015 | F39: =IFERROR(_xlfn.XLOOKUP(C39,Sheet2!B:B,Sheet2!E:E,"Missing",0),200) -> 0
A40: milking, milking porn, cock milking, milking fetish, milking machine, milking xxx, milking blowjob, milking domination, prostate milking, milking creampie, milking video, milking orgasm | B40: {=INDEX(_xlfn.TEXTSPLIT(A40,","),1)} -> milking | C40: =IFERROR(_xlfn.XLOOKUP(B40,Sheet2!A:A,Sheet2!B:B,"Missing",0),200) -> 100.07146 | D40: =IFERROR(_xlfn.XLOOKUP(B40,Sheet2!A:A,Sheet2!C:C,"Missing",0),200) -> 1 | E40: =IFERROR(_xlfn.XLOOKUP(B40,Sheet2!A:A,Sheet2!D:D,"Missing",0),200) -> 100.07146 | F40: =IFERROR(_xlfn.XLOOKUP(C40,Sheet2!B:B,Sheet2!E:E,"Missing",0),200) -> 0
A41: machine, sex machine porn, fucking machine, machine penetration, machine xxx, machine blowjob, machine anal, machine milf, machine dildo, sex machine milfs, extreme machine, bondage machine | B41: {=INDEX(_xlfn.TEXTSPLIT(A41,","),1)} -> machine | C41: =IFERROR(_xlfn.XLOOKUP(B41,Sheet2!A:A,Sheet2!B:B,"Missing",0),200) -> 100.07603 | D41: =IFERROR(_xlfn.XLOOKUP(B41,Sheet2!A:A,Sheet2!C:C,"Missing",0),200) -> 1 | E41: =IFERROR(_xlfn.XLOOKUP(B41,Sheet2!A:A,Sheet2!D:D,"Missing",0),200) -> 100.07603 | F41: =IFERROR(_xlfn.XLOOKUP(C41,Sheet2!B:B,Sheet2!E:E,"Missing",0),200) -> 0
A42: master, master porn, master domination, bdsm master, master xxx, master milf, master fetish, sex master, master blowjob, master anal, master roleplay, master video | B42: {=INDEX(_xlfn.TEXTSPLIT(A42,","),1)} -> master | C42: =IFERROR(_xlfn.XLOOKUP(B42,Sheet2!A:A,Sheet2!B:B,"Missing",0),200) -> 100.08792 | D42: =IFERROR(_xlfn.XLOOKUP(B42,Sheet2!A:A,Sheet2!C:C,"Missing",0),200) -> 1 | E42: =IFERROR(_xlfn.XLOOKUP(B42,Sheet2!A:A,Sheet2!D:D,"Missing",0),200) -> 100.08792 | F42: =IFERROR(_xlfn.XLOOKUP(C42,Sheet2!B:B,Sheet2!E:E,"Missing",0),200) -> 0
A43: toilet, toilet porn, toilet fetish, toilet xxx, toilet milf, toilet domination, toilet anal, toilet blowjob, using toilet fetish, toilet roleplay, extreme toilet play, toilet cam | B43: {=INDEX(_xlfn.TEXTSPLIT(A43,","),1)} -> toilet | C43: =IFERROR(_xlfn.XLOOKUP(B43,Sheet2!A:A,Sheet2!B:B,"Missing",0),200) -> 100.09983 | D43: =IFERROR(_xlfn.XLOOKUP(B43,Sheet2!A:A,Sheet2!C:C,"Missing",0),200) -> 1 | E43: =IFERROR(_xlfn.XLOOKUP(B43,Sheet2!A:A,Sheet2!D:D,"Missing",0),200) -> 100.09983 | F43: =IFERROR(_xlfn.XLOOKUP(C43,Sheet2!B:B,Sheet2!E:E,"Missing",0),200) -> 0
A44: trans, trans porn, shemale porn, shemale sex, sexy trans girl, trans cam, trans video, trans fetish, trans blowjob, shemale anal, trans big tits, shemale cock | B44: {=INDEX(_xlfn.TEXTSPLIT(A44,","),1)} -> trans | C44: =IFERROR(_xlfn.XLOOKUP(B44,Sheet2!A:A,Sheet2!B:B,"Missing",0),200) -> 100.103 | D44: =IFERROR(_xlfn.XLOOKUP(B44,Sheet2!A:A,Sheet2!C:C,"Missing",0),200) -> 1 | E44: =IFERROR(_xlfn.XLOOKUP(B44,Sheet2!A:A,Sheet2!D:D,"Missing",0),200) -> 100.103 | F44: =IFERROR(_xlfn.XLOOKUP(C44,Sheet2!B:B,Sheet2!E:E,"Missing",0),200) -> 0
A45: rope, rope porn, rope bondage, rope milf, rope xxx, rope sex, rope blowjob, japanese rope, rope fetish, rope slave, rope milf sex, rope amateur | B45: {=INDEX(_xlfn.TEXTSPLIT(A45,","),1)} -> rope | C45: =IFERROR(_xlfn.XLOOKUP(B45,Sheet2!A:A,Sheet2!B:B,"Missing",0),200) -> 100.50426 | D45: =IFERROR(_xlfn.XLOOKUP(B45,Sheet2!A:A,Sheet2!C:C,"Missing",0),200) -> 1 | E45: =IFERROR(_xlfn.XLOOKUP(B45,Sheet2!A:A,Sheet2!D:D,"Missing",0),200) -> 100.50426 | F45: =IFERROR(_xlfn.XLOOKUP(C45,Sheet2!B:B,Sheet2!E:E,"Missing",0),200) -> 0
A46: dental, dental porn, dentist fetish, dental xxx, dental sex, dental blowjob, dentist milf, dental compilation, dental tools fetish, patient dentist porn, dental anal, dental videos | B46: {=INDEX(_xlfn.TEXTSPLIT(A46,","),1)} -> dental | C46: =IFERROR(_xlfn.XLOOKUP(B46,Sheet2!A:A,Sheet2!B:B,"Missing",0),200) -> 1078.4153 | D46: =IFERROR(_xlfn.XLOOKUP(B46,Sheet2!A:A,Sheet2!C:C,"Missing",0),200) -> 10 | E46: =IFERROR(_xlfn.XLOOKUP(B46,Sheet2!A:A,Sheet2!D:D,"Missing",0),200) -> 107.84153 | F46: =IFERROR(_xlfn.XLOOKUP(C46,Sheet2!B:B,Sheet2!E:E,"Missing",0),200) -> 0
... A55: belly, belly porn, belly fetish, belly milf, belly sex, belly licking, belly cumshot, belly videos, pregnant belly porn, belly rub porn, belly button fetish, belly xxx | B55: {=INDEX(_xlfn.TEXTSPLIT(A55,","),1)} -> belly | C55: =IFERROR(_xlfn.XLOOKUP(B55,Sheet2!A:A,Sheet2!B:B,"Missing",0),200) -> 144.103 | D55: =IFERROR(_xlfn.XLOOKUP(B55,Sheet2!A:A,Sheet2!C:C,"Missing",0),200) -> 1 | E55: =IFERROR(_xlfn.XLOOKUP(B55,Sheet2!A:A,Sheet2!D:D,"Missing",0),200) -> 144.103 | F55: =IFERROR(_xlfn.XLOOKUP(C55,Sheet2!B:B,Sheet2!E:E,"Missing",0),200) -> 0
A56: JOI, JERK off instructions, Jerk Off Instructions, JOI sex, JOI fantasy, JOI encounter, JOI lovers, JOI relationship, JOI pleasure, JOI experience, JOI community, JOI fan, JOI content, JOI event | B56: {=INDEX(_xlfn.TEXTSPLIT(A56,","),1)} -> JOI | C56: =IFERROR(_xlfn.XLOOKUP(B56,Sheet2!A:A,Sheet2!B:B,"Missing",0),200) -> 145.341 | D56: =IFERROR(_xlfn.XLOOKUP(B56,Sheet2!A:A,Sheet2!C:C,"Missing",0),200) -> 1 | E56: =IFERROR(_xlfn.XLOOKUP(B56,Sheet2!A:A,Sheet2!D:D,"Missing",0),200) -> 145.341 | F56: All Platform
A57: creampie, creampie porn, creampie sex, creampie xxx, creampie compilation, anal creampie, asian creampie, teen creampie, creampie gangbang, double creampie, pov creampie, milf creampie | B57: {=INDEX(_xlfn.TEXTSPLIT(A57,","),1)} -> creampie | C57: =IFERROR(_xlfn.XLOOKUP(B57,Sheet2!A:A,Sheet2!B:B,"Missing",0),200) -> 3110.9768 | D57: =IFERROR(_xlfn.XLOOKUP(B57,Sheet2!A:A,Sheet2!C:C,"Missing",0),200) -> 21 | E57: =IFERROR(_xlfn.XLOOKUP(B57,Sheet2!A:A,Sheet2!D:D,"Missing",0),200) -> 148.14175 | F57: =IFERROR(_xlfn.XLOOKUP(C57,Sheet2!B:B,Sheet2!E:E,"Missing",0),200) -> 0
A58: power, power porn, power hentai, power xxx, naked power, power cosplay, power blowjob, power porn videos, chainsaw man power sex, power parody porn, power hentai videos, power nude hentai | B58: {=INDEX(_xlfn.TEXTSPLIT(A58,","),1)} -> power | C58: =IFERROR(_xlfn.XLOOKUP(B58,Sheet2!A:A,Sheet2!B:B,"Missing",0),200) -> 862.38698 | D58: =IFERROR(_xlfn.XLOOKUP(B58,Sheet2!A:A,Sheet2!C:C,"Missing",0),200) -> 5 | E58: =IFERROR(_xlfn.XLOOKUP(B58,Sheet2!A:A,Sheet2!D:D,"Missing",0),200) -> 172.4774 | F58: =IFERROR(_xlfn.XLOOKUP(C58,Sheet2!B:B,Sheet2!E:E,"Missing",0),200) -> 0
A59: wife, wife sex, sexy wife, hot wife, cheating wife, amateur wife, wife videos, wife swap, wife porn, mature wife, wife xxx, wife sharing | B59: {=INDEX(_xlfn.TEXTSPLIT(A59,","),1)} -> wife | C59: =IFERROR(_xlfn.XLOOKUP(B59,Sheet2!A:A,Sheet2!B:B,"Missing",0),200) -> 179.554 | D59: =IFERROR(_xlfn.XLOOKUP(B59,Sheet2!A:A,Sheet2!C:C,"Missing",0),200) -> 1 | E59: =IFERROR(_xlfn.XLOOKUP(B59,Sheet2!A:A,Sheet2!D:D,"Missing",0),200) -> 179.554 | F59: =IFERROR(_xlfn.XLOOKUP(C59,Sheet2!B:B,Sheet2!E:E,"Missing",0),200) -> 0
A60: hairy, hairy porn, hairy pussy, hairy milf, hairy teen, hairy creampie, hairy xxx, hairy blowjob, natural hairy porn, hairy anal, hairy fetish, hairy vintage porn | B60: {=INDEX(_xlfn.TEXTSPLIT(A60,","),1)} -> hairy | C60: =IFERROR(_xlfn.XLOOKUP(B60,Sheet2!A:A,Sheet2!B:B,"Missing",0),200) -> 1991.8966 | D60: =IFERROR(_xlfn.XLOOKUP(B60,Sheet2!A:A,Sheet2!C:C,"Missing",0),200) -> 11 | E60: =IFERROR(_xlfn.XLOOKUP(B60,Sheet2!A:A,Sheet2!D:D,"Missing",0),200) -> 181.08151 | F60: =IFERROR(_xlfn.XLOOKUP(C60,Sheet2!B:B,Sheet2!E:E,"Missing",0),200) -> 0
A61: emo, emo porn, emo teen, sexy emo, emo blowjob, emo sex, emo xxx, emo anal, emo milf, emo amateur, emo creampie, emo goth | B61: {=INDEX(_xlfn.TEXTSPLIT(A61,","),1)} -> emo | C61: =IFERROR(_xlfn.XLOOKUP(B61,Sheet2!A:A,Sheet2!B:B,"Missing",0),200) -> 100.2646 | D61: =IFERROR(_xlfn.XLOOKUP(B61,Sheet2!A:A,Sheet2!C:C,"Missing",0),200) -> 0 | E61: =IFERROR(_xlfn.XLOOKUP(B61,Sheet2!A:A,Sheet2!D:D,"Missing",0),200) -> 200 | F61: =IFERROR(_xlfn.XLOOKUP(C61,Sheet2!B:B,Sheet2!E:E,"Missing",0),200) -> 0
A62: alien, alien porn, alien sex, alien hentai, alien milf, alien xxx, alien fetish, alien blowjob, alien compilation, alien gangbang, alien roleplay, alien anime porn | B62: {=INDEX(_xlfn.TEXTSPLIT(A62,","),1)} -> alien | C62: =IFERROR(_xlfn.XLOOKUP(B62,Sheet2!A:A,Sheet2!B:B,"Missing",0),200) -> 100.11518 | D62: =IFERROR(_xlfn.XLOOKUP(B62,Sheet2!A:A,Sheet2!C:C,"Missing",0),200) -> 0 | E62: =IFERROR(_xlfn.XLOOKUP(B62,Sheet2!A:A,Sheet2!D:D,"Missing",0),200) -> 200 | F62: =IFERROR(_xlfn.XLOOKUP(C62,Sheet2!B:B,Sheet2!E:E,"Missing",0),200) -> 0
A63: doll, doll porn, sex doll porn, doll fetish, doll sex, life size doll porn, inflatable doll porn, doll milf, doll blowjob, doll xxx, doll videos, doll cosplay | B63: {=INDEX(_xlfn.TEXTSPLIT(A63,","),1)} -> doll | C63: =IFERROR(_xlfn.XLOOKUP(B63,Sheet2!A:A,Sheet2!B:B,"Missing",0),200) -> 100.10045 | D63: =IFERROR(_xlfn.XLOOKUP(B63,Sheet2!A:A,Sheet2!C:C,"Missing",0),200) -> 0 | E63: =IFERROR(_xlfn.XLOOKUP(B63,Sheet2!A:A,Sheet2!D:D,"Missing",0),200) -> 200 | F63: =IFERROR(_xlfn.XLOOKUP(C63,Sheet2!B:B,Sheet2!E:E,"Missing",0),200) -> 0
A64: pinay, pinay porn, sexy pinay, pinay sex, hot pinay, filipina porn, filipina sex, pinay video, pinay amateur, filipina milf, filipina xxx, pinay scandal | B64: {=INDEX(_xlfn.TEXTSPLIT(A64,","),1)} -> pinay | C64: =IFERROR(_xlfn.XLOOKUP(B64,Sheet2!A:A,Sheet2!B:B,"Missing",0),200) -> 100.05953 | D64: =IFERROR(_xlfn.XLOOKUP(B64,Sheet2!A:A,Sheet2!C:C,"Missing",0),200) -> 0 | E64: =IFERROR(_xlfn.XLOOKUP(B64,Sheet2!A:A,Sheet2!D:D,"Missing",0),200) -> 200 | F64: =IFERROR(_xlfn.XLOOKUP(C64,Sheet2!B:B,Sheet2!E:E,"Missing",0),200) -> 0
A65: maledom, maledom porn, male domination porn, maledom bdsm, maledom milf, maledom teen, maledom xxx, male dominating female, maledom blowjob, maledom anal, maledom slaves, alpha male porn | B65: {=INDEX(_xlfn.TEXTSPLIT(A65,","),1)} -> maledom | C65: =IFERROR(_xlfn.XLOOKUP(B65,Sheet2!A:A,Sheet2!B:B,"Missing",0),200) -> 100.05593 | D65: =IFERROR(_xlfn.XLOOKUP(B65,Sheet2!A:A,Sheet2!C:C,"Missing",0),200) -> 0 | E65: =IFERROR(_xlfn.XLOOKUP(B65,Sheet2!A:A,Sheet2!D:D,"Missing",0),200) -> 200 | F65: =IFERROR(_xlfn.XLOOKUP(C65,Sheet2!B:B,Sheet2!E:E,"Missing",0),200) -> 0
A66: french, french porn, french sex, french teen, french milf, french blowjob, french anal, french xxx, hot french girl, french amateur, french creampie, french videos | B66: {=INDEX(_xlfn.TEXTSPLIT(A66,","),1)} -> french | C66: =IFERROR(_xlfn.XLOOKUP(B66,Sheet2!A:A,Sheet2!B:B,"Missing",0),200) -> 100.05454 | D66: =IFERROR(_xlfn.XLOOKUP(B66,Sheet2!A:A,Sheet2!C:C,"Missing",0),200) -> 0 | E66: =IFERROR(_xlfn.XLOOKUP(B66,Sheet2!A:A,Sheet2!D:D,"Missing",0),200) -> 200 | F66: =IFERROR(_xlfn.XLOOKUP(C66,Sheet2!B:B,Sheet2!E:E,"Missing",0),200) -> 0
...

Sheet Keywords to launch
A1: keyword | B1: One Word
A2: stripper; stripper porn; stripper blowjob; stripper sex; stripper xxx; stripper amateur; hot stripper; busty stripper; stripper videos; teen stripper; stripper dancing; stripper anal | B2: stripper
A3: maid; maid porn; sexy maid; hot maid; french maid porn; maid blowjob; maid xxx; maid anal; maid milf; maid videos; naughty maid; asian maid | B3: maid
A4: femdom; femdom porn; femdom domination; femdom mistress; femdom milf; femdom slave; femdom fetish; femdom ass worship; femdom xxx; femdom pegging; femdom handjob; femdom cum | B4: femdom
A5: ahegao; ahegao porn; ahegao face; hentai ahegao; anime ahegao; cum ahegao; ahegao compilation; ahegao xxx; asian ahegao; ahegao teen; cosplay ahegao; big tits ahegao | B5: ahegao
A6: pregnant; pregnant porn; pregnant milf; pregnant teen; pregnant sex; pregnant creampie; pregnant blowjob; pregnant fetish; pregnant xxx; pregnant lesbian; pregnant anal; pregnant compilation | B6: pregnant
A7: goth; goth porn; goth girl; hot goth; goth blowjob; goth sex; goth amateur; goth anal; goth milf; goth xxx; goth cumshot; emo porn | B7: goth
A8: latex; latex porn; latex fetish; sexy latex; latex bdsm; latex xxx; latex mistress; latex milf; latex gloves fetish; latex anal; latex blowjob; latex videos | B8: latex
A9: feet; foot fetish; feet porn; sexy feet; feet worship; footjob; feet licking; feet xxx; feet cumshot; feet tease; feet milf; feet pics | B9: feet
A10: public; public porn; public sex; in public; public blowjob; public xxx; public fap; public fetish; public creampie; public amateur; public flashing; outdoor sex | B10: public
A11: orgy; orgy porn; orgy sex; group sex; amateur orgy; teen orgy; milf orgy; interracial orgy; lesbian orgy; orgy xxx; sex party porn; hardcore orgy | B11: orgy
A12: straight; straight porn; straight sex; straight couple sex; straight amateur; straight videos; straight blowjob; straight xxx; straight anal; straight creampie; straight fuck; straight teens | B12: straight
... A33: mature; mature porn; mature milf; mature woman; sexy mature; mature anal; mature creampie; mature big tits; mature xxx; mature blowjob; mature threesome; mature amateur | B33: mature
A34: clown; clown porn; clown sex; clown xxx; clown blowjob; clown milf; clown fetish; clown roleplay; clown compilation; clown anal; clown lingerie porn; clown gangbang | B34: clown | D34: STOP JERE
A35: stepmom; stepmom porn; hot stepmom; stepmom sex; mature stepmom; big tits stepmom; naughty stepmom; sexy stepmom; stepmom blowjob; stepmom videos; milf stepmom; stepmom anal | B35: stepmom
A36: club; club porn; sex club; swinger club; club sex video; club gangbang; night club porn; club orgy; club xxx; club fuck; club amateur; club teens | B36: club
A37: witch; witch porn; witch milf; witch sex; witch xxx; sexy witch; hentai witch; witch fetish; witch blowjob; witch strip; halloween witch porn; demon witch sex | B37: witch
A38: spanish; spanish porn; spanish sex; spanish milf; spanish teen; spanish anal; spanish blowjob; spanish videos; hot spanish girl; spanish xxx; spanish amateur; spanish creampie | B38: spanish
A39: triple; triple penetration porn; triple xxx; triple sex; triple milf; triple fetish; triple anal; double anal triple; triple creampie; triple blowjob; hardcore triple; triple gangbang | B39: triple
A40: milking; milking porn; cock milking; milking fetish; milking machine; milking xxx; milking blowjob; milking domination; prostate milking; milking creampie; milking video; milking orgasm | B40: milking
A41: machine; sex machine porn; fucking machine; machine penetration; machine xxx; machine blowjob; machine anal; machine milf; machine dildo; sex machine milfs; extreme machine; bondage machine | B41: machine
A42: master; master porn; master domination; bdsm master; master xxx; master milf; master fetish; sex master; master blowjob; master anal; master roleplay; master video | B42: master
A43: toilet; toilet porn; toilet fetish; toilet xxx; toilet milf; toilet domination; toilet anal; toilet blowjob; using toilet fetish; toilet roleplay; extreme toilet play; toilet cam | B43: toilet
A44: trans; trans porn; shemale porn; shemale sex; sexy trans girl; trans cam; trans video; trans fetish; trans blowjob; shemale anal; trans big tits; shemale cock | B44: trans
A45: rope; rope porn; rope bondage; rope milf; rope xxx; rope sex; rope blowjob; japanese rope; rope fetish; rope slave; rope milf sex; rope amateur | B45: rope
A46: dental; dental porn; dentist fetish; dental xxx; dental sex; dental blowjob; dentist milf; dental compilation; dental tools fetish; patient dentist porn; dental anal; dental videos | B46: dental
... A245: ai hentai; ai hentai porn; ai generated hentai; ai hentai xxx; ai doujin; ai hentai pics; ai hentai videos; ai anime hentai; ai waifu porn; ai anime girl porn; ai hentai gif; ai anime xxx | B245: ai hentai

Sheet Sheet3
A1: General | C1: Creative ID | E1: Trans | G1: Creative ID | I1: Gay | J1: Video names | K1: Creative ID
A2: Vid ID | B2: Vid Name | E2: Vid ID | F2: Vid Name | I2: Vid ID | J2: Vid Name
A3: 6673274 | B3: AIPORNISHERE_MISSIONARY_converted | C3: 1032467881 | E3: 6673272 | F3: AIPORNISHERE_TRANSINTENSE_converted | G3: 1032467951 | I3: 6577040 | J3: AI PORN IS HERE V2 Gay2 | K3: 1032473171
A4: 6696906 | B4: ANIMETV_vBF | C4: 1032539081 | E4: 6696906 | F4: ANIMETV_vBF | G4: 1032539081 | I4: 6696902 | J4: TALKINGAD_GAY-vBF | K4: 1032539091
A5: 6696904 | B5: TALKINGAD_GENERAL_vBF | C5: 1032539101 | E5: 6696904 | F5: TALKINGAD_GENERAL_vBF | G5: 1032539101
A6: 6696900 | B6: WALKINGSELFIE_GENERAL_vBF | C6: 1032539111 | E6: 6696900 | F6: WALKINGSELFIE_GENERAL_vBF | G6: 1032539111
A11: Top TJ ads
B12: AIPORNISHERE_INDIAN | C12: 1032166452 | F12: AIPORNISHERE_INDIAN | G12: 1032166452 | J12: AIPORNISHERE_INDIAN | K12: 1032166452
B13: New Porn Vid | C13: 1031965702 | F13: New Porn Vid | G13: 1031965702 | J13: New Porn Vid | K13: 1031965702
B14: AIPORNISHERE_GOTH | C14: 1032166482 | F14: AIPORNISHERE_GOTH | G14: 1032166482 | J14: AIPORNISHERE_GOTH | K14: 1032166482
